# 오류처리

프로그램이 오류를 일으켰을 때 감지하고 회복시키는 과정
오류가 발생할 수 있는 가능성이 있는 기능 구현시에는 항상 오류 발생이 가능함을 고려하고 있어야 함
ex) 디스크의 파일을 읽어올 때 → 파일이 존재하지 않거나, 읽기 권한이 없거나, 잘못된 파일인 경우 오류..

## 오류의 표현

스위프트에서 오류(Error)는 `Error`라는 프로토콜을 준수하는 타입의 값을 통해 표현
→ 열거형은 오류의 종류를 나타내기에 아주 적합한 기능이다.

```swift
enum VendingMachineError: Error { //Error 프로토콜 채택 -> 오류처리를 위한 타입이군! 
       case insufficientFunds //자금 부족
       case outOfStock //품절
}
```

이렇게 오류의 종류를 미리 예상한 후, 오류때문에 다음 동작이 정상적으로 진행되지 않을 시 오류를 던져주면 된다 → `throw` 구문 사용 
ex) 자금이 부족해서 오류 발생시: `throw VendingMachineError.insufficientFunds`

## 오류 포착 및 처리

오류가 던져지는 것에 대비하여 **그것을 처리**하기 위한 코드
ex) 던져진 오류가 뭔지 판단하여 다시 문제를 해결, 다른 방법으로 문제 해결 시도, 오류를 알리고 사용자에게 선택 권한을 넘겨서 다음에 어떤 동작을 할 것인지 선택 유도 등

### 함수에서 발생한 오류 알리기

함수에서 발생한 오류를 해당 함수를 호출한 코드에 알리는 방법
어디서 오류를 던지고 받을 것인가? 중요
`try`로 던져진 오류를 받을 수 있다. 

<오류 던지기>

`throws` : 함수, 매서드, 이니셜라이저의 매개변수 뒤에 작성 

`func cannotThrowErrors() -> String` → `func canThrowErrors()**throws**-> String`

- 재고 부족 / 2. 돈 부족 일때 오류 발생
- guard 문을 썼다는 것은 오류가 발생할 수도 있다는 소리니 오류를 던져야됨 → throw 써주기^^

```swift
enum VendingMachineError: Error { //오류의 표현
    case insufficientFunds
    case outOfStock
}

class VendingMachine {
    private var itemStock: Int = 2 //재고
    private var coinsDeposited: Int = 0 //넣은 돈

    var isOutOfStock: Bool { //계산 속성 : get만 있어서 get블록 생략한 것
        return itemStock < 1 //1보다 작으면 true 리턴하는군 !!
    }

    var price: Int { //계산 속성 -> 왜 굳이 계산속성으로 했지..? 아 메서드에서 갖다쓰려고
        return 100
    }

    func insertCoin(amount: Int) {
        coinsDeposited += amount
    }

    //오류를 던질 수 있는 매서드 : throw를 총 두군데 써준다. (매개변수 뒤, guard 문 안 오류 발생할 구간)
    func vend(amount: Int = 1) **throws** -> String {
        guard isOutOfStock == false else { //true: 재고가 없을 때(예외상황) -> 오류 발생 알림
            **throw** VendingMachineError.outOfStock
        }
        guard coinsDeposited >= price * amount else { //넣은 돈보다 가격이 더 클 때(예외상황) -> 오류발생 알림
            **throw** VendingMachineError.insufficientFunds
        }

        coinsDeposited = coinsDeposited - (amount * price) //넣은 돈에서 상품개수랑 가격 곱한 상품가격 빼고 나머지

        return "상품" //엥? 이건뭐야 -> 아 나중에 오류 없으면 "상품 받았음" 이라고 프린트됨
    }

}
```

`VendingMachine` 클래스는 오류를 던질 수 있는 `vend(amount:)`매서드가 있는데, 
이 `vend(amount:)` 매서드를 호출하는 함수도 오류를 던질 수 있어야 해서 
`orderSoda(amount:machine:)`함수도 오류를 던질 수 있게 처리해줌
→ 아니 근데 그럼 이런 던져진 오류들을 받는 곳은 어디냐??? 그 메서드를 사용하는 곳 

그런데....

오류를 던질 수 있는 함수.. 등을 호출하는 코드(함수..)는 반드시 오류를 처리할 수 있는 구문이 있어야 한다. → 지금은 없어가지고 오류가 발생 (오직 오류를 받는 `try`뿐...) (세트인 `do-catch`가 없다!!)

`**try` 의 의미: ‘이 함수가 오류가 발생할 수도 있는데, 한번 시도해볼게요.’**

그래서 **오류가 발생하는 메소드 앞**에 넣어두는거임

```swift
func orderSoda(amount: Int = 1, machine: VendingMachine) throws {
    let item: String = **try** machine.vend(amount: amount)**//오류 발생 메소드 앞에 try 적어줌**
    print("\(item)받았음")
}

let machine: VendingMachine = VendingMachine()
try orderSoda(amount: 3, machine: machine)
```

![스크린샷 2021-09-01 오후 11.43.16.png](https://s3-us-west-2.amazonaws.com/secure.notion-static.com/b89dd3bd-c287-4e41-b64e-38d9e6cf4e22/스크린샷_2021-09-01_오후_11.43.16.png)

### do-catch 구문을 이용한 오류처리

그래서 지금 오류처리하는 방법을 알아보자

함수, 매서드, 이니셜라이저 등에서 오류를 던져주면 오류 발생을 전달받은 코드 블록은 `do-catch` 구문으로 오류를 처리한다. 

`do`절 내부에서 오류를 던지면 `catch`절에서 오류를 전달받아 적절하게 처리함.

`do-catch` 구문

```swift
do {
    try 오류 발생 가능코드
    오류가 발생하지 않으면 실행할 코드
} catch 오류 패턴 1 { 
    처리 코드
} catch 오류 패턴 2 {
    처리 코드
}
```

예시

```swift
//soda 를 주문하는 함수에서 오류처리를 해줌
do {
    **try** **orderSoda(amount: 4, machine: machine)** //**오류발생위험** 있지만 한번 시도해볼게 ~ try ~ 
} catch VendingMachineError.insufficientFunds {
    print("돈 모자람")
} catch VendingMachineError.outOfStock {
    print("재고 부족")
}
```

근데 사실... orderSoda를 호출하는 곳 말고 자판기 스스로 오류처리를 해주는게 좋은데

자판기는 오류를 던져주기만 해서, 자판기에게 요청하는 함수 orderSoda 에서 처리해줌 

이렇게

자판기에서 던져진 오류를 `orderSoda(amount:machine:)` 함수에서 do-catch 구문을 사용해 처리

```swift
func orderSoda(amount: Int = 1, machine: VendingMachine) {
    **do** {
        let item: String = **try** machine.vend(amount: amount)
        print("\(item) 받았음")
    } **catch** VendingMachineError.insufficientFunds {
        print("돈 모자람")
    } **catch** VendingMachineError.outOfStock {
        print("재고 부족")
    } **catch** {
        print(error)
    }
}

let machine: VendingMachine = VendingMachine()
orderSoda(amount: 3, machine: machine) //여기서 머신은 바로 위 인스턴스 머신 ~
```

- do-try-catch 이해하는데 참고함
    
    [[Swift] 예외처리 (throws, do-catch, try) 하기](https://twih1203.medium.com/swift-%EC%98%88%EC%99%B8%EC%B2%98%EB%A6%AC-throws-do-catch-try-%ED%95%98%EA%B8%B0-c0f320e61f62)
    

- 전체 코드
    
    ```swift
    enum VendingMachineError: Error { //오류의 표현
        case insufficientFunds
        case outOfStock
    }
    
    class VendingMachine {
        private var itemStock: Int = 2 //재고
        private var coinsDeposited: Int = 0 //넣은 돈
    
        var isOutOfStock: Bool { //계산 속성 : get만 있어서 get블록 생략한 것
            return itemStock < 1 //1보다 작으면 true 리턴하는군 !!
        }
    
        var price: Int { //계산 속성 -> 왜 굳이 계산속성으로 했지..? 아 메서드에서 갖다쓰려고
            return 100
        }
    
        func insertCoin(amount: Int) {
            coinsDeposited += amount
        }
    
        //오류를 던질 수 있는 매서드 : throw를 총 두군데 써준다. (매개변수 뒤, guard 문 안 오류 발생할 구간)
        func vend(amount: Int = 1) throws -> String {
            guard isOutOfStock == false else { //true: 재고가 없을 때(예외상황) -> 오류 발생 알림
                throw VendingMachineError.outOfStock
            }
            guard coinsDeposited >= price * amount else { //넣은 돈보다 가격이 더 클 때(예외상황) -> 오류발생 알림
                throw VendingMachineError.insufficientFunds
            }
    
            coinsDeposited = coinsDeposited - (amount * price) //넣은 돈에서 상품개수랑 가격 곱한 상품가격 빼고 나머지
    
            return "상품" //엥? 이건뭐야 -> 아 나중에 오류 없으면 "상품 받았음" 이라고 프린트됨
        }
    
    }
    
    //던져진 오류를 받아서 처리해주는 모습 ~~~~
    func orderSoda(amount: Int = 1, machine: VendingMachine) {
        do {
            let item: String = try machine.vend(amount: amount)
            print("\(item) 받았음")
        } catch VendingMachineError.insufficientFunds {
            print("돈 모자람")
        } catch VendingMachineError.outOfStock {
            print("재고 부족")
        } catch {
            print(error)
        }
    }
    
    let machine: VendingMachine = VendingMachine()
    orderSoda(amount: 3, machine: machine) //여기서 머신은 바로 위 인스턴스 머신 ~
    ```
